  File "/opt/venv/lib/python3.12/site-packages/gunicorn/workers/base.py", line 134, in init_process

    self.load_wsgi()

  File "/opt/venv/lib/python3.12/site-packages/gunicorn/workers/base.py", line 146, in load_wsgi

    self.wsgi = self.app.wsgi()

                ^^^^^^^^^^^^^^^

  File "/opt/venv/lib/python3.12/site-packages/gunicorn/app/base.py", line 67, in wsgi

    self.callable = self.load()

                    ^^^^^^^^^^^

  File "/opt/venv/lib/python3.12/site-packages/gunicorn/app/wsgiapp.py", line 58, in load

    return self.load_wsgiapp()

           ^^^^^^^^^^^^^^^^^^^

  File "/opt/venv/lib/python3.12/site-packages/gunicorn/app/wsgiapp.py", line 48, in load_wsgiapp

    return util.import_app(self.app_uri)

           ^^^^^^^^^^^^^^^^^^^^^^^^^^^^^

  File "/opt/venv/lib/python3.12/site-packages/gunicorn/util.py", line 371, in import_app

    mod = importlib.import_module(module)

          ^^^^^^^^^^^^^^^^^^^^^^^^^^^^^^^

  File "/root/.nix-profile/lib/python3.12/importlib/__init__.py", line 90, in import_module

    return _bootstrap._gcd_import(name[level:], package, level)

           ^^^^^^^^^^^^^^^^^^^^^^^^^^^^^^^^^^^^^^^^^^^^^^^^^^^^

  File "<frozen importlib._bootstrap>", line 1387, in _gcd_import

  File "<frozen importlib._bootstrap>", line 1360, in _find_and_load

  File "<frozen importlib._bootstrap>", line 1331, in _find_and_load_unlocked

  File "<frozen importlib._bootstrap>", line 935, in _load_unlocked

  File "<frozen importlib._bootstrap_external>", line 995, in exec_module

  File "<frozen importlib._bootstrap>", line 488, in _call_with_frames_removed

  File "/app/app.py", line 777, in <module>

    j: Node(  # Создаем объекты Node для других узлов

       ^^^^^^^^^^^^^^^^^^^^^^^^^^^^^^^^^^^^^^^^^^^^^^

  File "/app/app.py", line 225, in __init__

    asyncio.create_task(self.sync_blockchain())

  File "/root/.nix-profile/lib/python3.12/asyncio/tasks.py", line 417, in create_task

    loop = events.get_running_loop()

           ^^^^^^^^^^^^^^^^^^^^^^^^^

RuntimeError: no running event loop

[2025-05-11 19:20:56 +0000] [7] [INFO] Worker exiting (pid: 7)

sys:1: RuntimeWarning: coroutine 'Node.sync_blockchain' was never awaited

RuntimeWarning: Enable tracemalloc to get the object allocation traceback

[2025-05-11 19:20:56 +0000] [1] [ERROR] Worker (pid:7) exited with code 3

Traceback (most recent call last):

  File "/opt/venv/lib/python3.12/site-packages/gunicorn/arbiter.py", line 209, in run

    self.sleep()

  File "/opt/venv/lib/python3.12/site-packages/gunicorn/arbiter.py", line 360, in sleep

    ready = select.select([self.PIPE[0]], [], [], 1.0)

            ^^^^^^^^^^^^^^^^^^^^^^^^^^^^^^^^^^^^^^^^^^

  File "/opt/venv/lib/python3.12/site-packages/gunicorn/arbiter.py", line 242, in handle_chld

    self.reap_workers()

  File "/opt/venv/lib/python3.12/site-packages/gunicorn/arbiter.py", line 530, in reap_workers

    raise HaltServer(reason, self.WORKER_BOOT_ERROR)

gunicorn.errors.HaltServer: <HaltServer 'Worker failed to boot.' 3>

 

During handling of the above exception, another exception occurred:

 

Traceback (most recent call last):

  File "/opt/venv/bin/gunicorn", line 8, in <module>

    sys.exit(run())

             ^^^^^

  File "/opt/venv/lib/python3.12/site-packages/gunicorn/app/wsgiapp.py", line 67, in run

    WSGIApplication("%(prog)s [OPTIONS] [APP_MODULE]").run()

  File "/opt/venv/lib/python3.12/site-packages/gunicorn/app/base.py", line 236, in run

    super().run()

  File "/opt/venv/lib/python3.12/site-packages/gunicorn/app/base.py", line 72, in run

    Arbiter(self).run()

  File "/opt/venv/lib/python3.12/site-packages/gunicorn/arbiter.py", line 229, in run

    self.halt(reason=inst.reason, exit_status=inst.exit_status)

  File "/opt/venv/lib/python3.12/site-packages/gunicorn/arbiter.py", line 342, in halt

    self.stop()

  File "/opt/venv/lib/python3.12/site-packages/gunicorn/arbiter.py", line 396, in stop

    time.sleep(0.1)

  File "/opt/venv/lib/python3.12/site-packages/gunicorn/arbiter.py", line 242, in handle_chld

    self.reap_workers()

  File "/opt/venv/lib/python3.12/site-packages/gunicorn/arbiter.py", line 530, in reap_workers

    raise HaltServer(reason, self.WORKER_BOOT_ERROR)

gunicorn.errors.HaltServer: <HaltServer 'Worker failed to boot.' 3>